

<robot name="2_R_robot">
    <link name="fixed_base">
     <visual>
       <geometry>
         <sphere radius="0.1"/>
       </geometry>
       </visual>
    </link>
    
    <link name="link_1">
    <visual>
      <geometry>
        <cylinder length="0.8" radius="0.05"/>
        </geometry>
          <origin xyz="0 -0.05 0.16" rpy="-2 0 0"/>
     </visual>
    </link>

    <link name="link_2">
     <visual>
        <geometry>
          <cylinder length="0.8" radius="0.05"/>
            </geometry>
      <origin xyz="-0.172 -0.69 0.35" rpy="4 0 0"/>
       </visual>
</link>
    <joint name="Revolute_joint_1" type="revolute">
    <parent link="fixed_base"/>
      <child link="link_1"/>
      <origin xyz="0 -0.25 0"/>
      <limit lower="-1.57" upper="1.57" effort="10" velocity="3"/>
        </joint>
    <joint name="Revolute_joint_2" type="revolute">
       <parent link="link_1"/>
      <child link="link_2"/>
      <origin xyz="0.17 0 0.22"/>
      <limit lower="-1.57" upper="1.57" effort="10" velocity="3"/>
      </joint>
      </robot>
